Workbook

Sheet Raw Data
A1: Free People Bestsellers Analysis
A2: Product Name | B2: Style No. | C2: Product Category | D2: Subcategory | E2: Price | F2: Original Price | G2: Sale Status | H2: Discount % | I2: Primary Color | J2: Color Family | K2: Fabric/Material | L2: Material Type | M2: Pattern/Print | N2: Style/aesthetic | O2: Rating (Stars) | P2: Number of Reviews | Q2: Availability | R2: Color Options Count | S2: Notes (If needed)
A3: Opal Rollneck Knit Sweater | B3: 100632421 | C3: Sweaters | D3: Pullovers | E3: 98 | F3: 98 | G3: Full Price | H3: 0 | I3: Tea | J3: Earthy Neutrals | K3: BCI Cotton, Acrylic | L3: Mixed | M3: Textured Knit | N3: Casual Basic | O3: 4.2 | P3: 240 | Q3: Limited Availability | R3: 15 | S3: 57% BCI Cotton, 43% Acrylic; Oversized textured knit; Sizes: S and M unavailable
A4: Spotlight Washed Barrel Chino Trousers | B4: 103179669 | C4: Pants | D4: Chino Trousers | E4: 128 | F4: 128 | G4: Full Price | H4: 0 | I4: Tofu | J4: Neutrals | K4: Cotton, Rayon, Linen | L4: Mixed | M4: Solid | N4: Casual Basic | O4: 4.3 | P4: 160 | Q4: Available | R4: 9 | S4: 56% Cotton, 32% Rayon, 12% Linen; Sizes run small
A5: Better On Sweatshirt | B5: 100458652 | C5: Tops | D5: Hoodies + Sweatshirts | E5: 78 | F5: 78 | G5: Full Price | H5: 0 | I5: Coconut Milk | J5: White | K5: Cotton | L5: Natural | M5: Solid | N5: Basic Casual | O5: 4.4 | P5: 31 | Q5: Available | R5: 8 | S5: 100% Cotton; Oversized
A6: Chelsea Funnel-Neck Jacket | B6: 107456675 | C6: Jackets | D6: Funnel-Neck Jackets | E6: 168 | F6: 168 | G6: Full Price | H6: 0 | I6: Flint Stone | J6: Greys | K6: Polyester, Cotton, Polyamide | L6: Synthetic | M6: Solid | N6: Casual Basic | O6: 4.3 | P6: 11 | Q6: Available | R6: 4 | S6: 49% Polyester, 41% Cotton, 10% Polyamide ; Low review count
A7: Margaux Tank | B7: 107496283 | C7: Tops | D7: Tanks | E7: 78 | F7: 78 | G7: Full Price | H7: 0 | I7: White Swan | J7: White | K7: Polyester | L7: Synthetic | M7: Solid | N7: Casual Basic | O7: 4.3 | P7: 8 | Q7: Available | R7: 5 | S7: 100% Polyester; Sizes run small; Low review count
A8: Spotlight Washed Barrel Chino Trousers | B8: 103179669 | C8: Pants | D8: Chino Trousers | E8: 128 | F8: 128 | G8: Full Price | H8: 0 | I8: Dusty Olive | J8: Earthy Neutrals | K8: Cotton, Rayon, Linen | L8: Mixed | M8: Solid | N8: Casual Basic | O8: 4.3 | P8: 160 | Q8: Limited Availability | R8: 9 | S8: 56% Cotton, 32% Rayon, 12% Linen; Sizes run small; Long fit size unavailable
A9: Ventura Oversized Aviator Sunglasses | B9: 60094133 | C9: Accessories | D9: Sunglasses + Eyewear | E9: 25 | F9: 25 | G9: Full Price | H9: 0 | I9: Black/Berry | J9: Darks | K9: Base Metal, Plastic | L9: Mixed | M9: Solid | N9: Retro Aviator | O9: 3.4 | P9: 139 | Q9: Available | R9: 6 | S9: Oversized; Low rating
A10: We The Free Good Luck Barrel Overalls | B10: 86798519 | C10: Jeans | D10: Overalls + Jumpsuits | E10: 148 | F10: 148 | G10: Full Price | H10: 0 | I10: Ultra Light Beam | J10: Blue Denim | K10: Cotton, Lyocell, Recycled Linen, Elastane | L10: Mixed | M10: Solid | N10: Casual Basic | O10: 4.3 | P10: 451 | Q10: Limited Availability | R10: 9 | S10: Limited sizes: Only L and XL available; Long fit unavailable
A11: We The Free Baby Emerson Tote Bag | B11: 97540942 | C11: Accessories | D11: Bags | E11: 178 | F11: 178 | G11: Full Price | H11: 0 | I11: Salt | J11: White | K11: Leather | L11: Natural | M11: Solid | N11: Everyday Classic | O11: 4.3 | P11: 415 | Q11: Available | R11: 9 | S11: 100% Leather
A12: Margot SoftSpun Sweater Tee | B12: 101764561 | C12: Tops | D12: Tees | E12: 98 | F12: 98 | G12: Full Price | H12: 0 | I12: Marigold Melange | J12: Warms | K12: Polyester, Acrylic, Polyamide, Elastine | L12: Synthetic | M12: Solid | N12: Casual Basic | O12: 4 | P12: 43 | Q12: Available | R12: 13 | S12: 54% Polyester, 36% Acrylic, 7% Polyamide, 3% Elastane; Oversized; XL unavailable
A13: So Soft Seamless Modal Long Sleeve | B13: 101347284 | C13: Tops | D13: Intimates | E13: 40 | F13: 40 | G13: Full Price | H13: 0 | I13: Whispering Willow | J13: Earthy Neutrals | K13: Polyamide, Elastane, Modal | L13: Mixed | M13: Solid | N13: Casual Basic | O13: 4.2 | P13: 81 | Q13: Limited Availability | R13: 12 | S13: 15% Polyamide, 5% Elastane, 80% Modal; Runs small; Sizes: M and L unavailable
A14: Sailor Straw Hat | B14: 107645277 | C14: Accessories | D14: Hats | E14: 38 | F14: 38 | G14: Full Price | H14: 0 | I14: Neutral | J14: Neutrals | K14: Paper | L14: Natural | M14: Woven/Open Weave | N14: Everyday Classic | O14: 4.6 | P14: 7 | Q14: Available | R14: 5 | S14: 100% Paper; Low review count
A15: So Silk Badana | B15: 96577754 | C15: Accessories | D15: Scarves + Bandanas | E15: 48 | F15: 48 | G15: Full Price | H15: 0 | I15: Springtime Print Chocolate | J15: Earthy Neutrals | K15: Silk | L15: Natural | M15: Paisley Print | N15: Everyday Classic | O15: 4 | P15: 42 | Q15: Available | R15: 13 | S15: 100% Silk
A16: See You Soon Studded Tote | B16: 100468586 | C16: Accessories | D16: Bags | E16: 198 | F16: 198 | G16: Full Price | H16: 0 | I16: Bitter Bark | J16: Earthy Neutrals | K16: Leather | L16: Natural | M16: Solid/Studded | N16: Everyday Classic | O16: 4.1 | P16: 7 | Q16: Available | R16: 2 | S16: 100% Leather; Studded; Low review count
A17: We The Free Peggy Tee | B17: 107581175 | C17: Tops | D17: Tees | E17: 48 | F17: 48 | G17: Full Price | H17: 0 | I17: Clean Ivory | J17: Off-Whites | K17: Cotton | L17: Natural | M17: Solid | N17: Casual Basic | O17: 4.3 | P17: 22 | Q17: Limited Availability | R17: 7 | S17: 100% Cotton; Limited sizes: Only sizes: L and XL available
A18: Opal Knit Cardi | B18: 105616825 | C18: Sweaters | D18: Cardigans | E18: 168 | F18: 168 | G18: Full Price | H18: 0 | I18: Black | J18: Darks | K18: Cotton, Acrylic | L18: Mixed | M18: Textured Knit | N18: Cozy | O18: 4 | P18: 33 | Q18: Available | R18: 3 | S18: 57% Cotton, 43% Acrylic
A19: Mismatch Magnolia Sandals | B19: 99005373 | C19: Shoes | D19: Sandals | E19: 128 | F19: 128 | G19: Full Price | H19: 0 | I19: Tan Suede | J19: Earthy Neutrals | K19: Leather, Rubber | L19: Mixed | M19: Solid/Floral Detail | N19: Everyday Classic | O19: 4.1 | P19: 21 | Q19: Limited Availability | R19: 5 | S19: Limited sizes: Only size US 6 available
... A35: We The Free Palm Springs Pullover | B35: 96774302 | C35: Sweaters | D35: Pullovers | E35: 78 | F35: 78 | G35: Full Price | H35: 0 | I35: Clean Ivory | J35: Off-Whites | K35: Cotton | L35: Natural | M35: Solid | N35: Casual Basic | O35: 4.4 | P35: 142 | Q35: Available | R35: 12 | S35: 100% Cotton; Oversized
A36: Lady Lux Layering Top | B36: 58381005 | C36: Tops | D36: Intimates | E36: 40 | F36: 40 | G36: Full Price | H36: 0 | I36: Black | J36: Dark Neutral | K36: Elastane, Nylon | L36: Synthetic | M36: Floral | N36: Intimates | O36: 4.4 | P36: 727 | Q36: Limited Availability | R36: 13 | S36: 15% Elastane, 85% Nylon; Limited sizes: M, L, and XL unavailable
A37: Sabo East West Bag | B37: 100073840 | C37: Accessories | D37: Bags | E37: 148 | F37: 148 | G37: Full Price | H37: 0 | I37: Saddle | J37: Earthy Neutrals | K37: Leather | L37: Natural | M37: Solid | N37: Casual Basic | O37: 3.5 | P37: 8 | Q37: Available | R37: 1 | S37: Low review count
A38: Tilly Skinny Silk Convertible Scarf | B38: 101374734 | C38: Accessories | D38: Scarves + Bandanas | E38: 28 | F38: 28 | G38: Full Price | H38: 0 | I38: Ditsy Dots Pink | J38: Pink/Multicolor | K38: Silk | L38: Natural | M38: Floral | N38: Boho | O38: 4 | P38: 49 | Q38: Available | R38: 11 | S38: 100% Silk
A39: We The Free Montana Shorts | B39: 94588803 | C39: Pants | D39: Shorts | E39: 78 | F39: 78 | G39: Full Price | H39: 0 | I39: Haven | J39: Blue Denim | K39: Cotton | L39: Natural | M39: Solid | N39: Casual Basic | O39: 4.1 | P39: 85 | Q39: Limited Availability | R39: 6 | S39: 100% Cotton
A40: VIBAe Roma Mules | B40: 98060296 | C40: Shoes | D40: Mules | E40: 200 | F40: 200 | G40: Full Price | H40: 0 | I40: Cognac Brown | J40: Earthy Neutrals | K40: Leather, Rubber | L40: Mixed | M40: Solid | N40: Casual Basic | O40: 4.9 | P40: 19 | Q40: Available | R40: 5 | S40: Limited sizes: Sizes 26 and 27 unavailable
A41: We The Free Baby Asher Tote | B41: 106790777 | C41: Accessories | D41: Bags | E41: 198 | F41: 198 | G41: Full Price | H41: 0 | I41: Espresso | J41: Earthy Neutrals | K41: Leather | L41: Natural | M41: Solid | N41: Everyday Classic | O41: 4 | P41: 7 | Q41: Available | R41: 3 | S41: Limited review count
A42: We The Free Fringe Out Vegan Suede Jacket | B42: 87495743 | C42: Jackets | D42: Fringe Jacket | E42: 168 | F42: 168 | G42: Full Price | H42: 0 | I42: Toasted Coconut | J42: Earthy Neutrals | K42: Polyester, Elastane | L42: Synthetic | M42: Fringe | N42: Vintage | O42: 4.4 | P42: 78 | Q42: Available | R42: 3 | S42: 87% Polyester; 13% Elastane; Oversized
A43: Belle Rosette Claw Clip | B43: 106139603 | C43: Accessories | D43: Hair Clips | E43: 18 | F43: 18 | G43: Full Price | H43: 0 | I43: Sage | J43: Earthy Neutrals | K43: Polyester,Plastic | L43: Synthetic | M43: Solid | N43: Romantic | O43: 4.4 | P43: 7 | Q43: Available | R43: 5 | S43: 60% Polyester, 40% Plastic; Low review count
A44: Understated Leather Wide Eyes Suede Fringe Collar | B44: 100212216 | C44: Accessories | D44: Scarves + Bandanas | E44: 98 | F44: 98 | G44: Full Price | H44: 0 | I44: Moss | J44: Earthy Neutrals | K44: Leather | L44: Natural | M44: Fringe | N44: Vintage | O44: 4.6 | P44: 29 | Q44: Available | R44: 5 | S44: 100% Leather
A45: Moonflower Pull-On Balloon Pants | B45: 104179064 | C45: Pants | D45: Balloon Pants | E45: 98 | F45: 98 | G45: Full Price | H45: 0 | I45: Sage | J45: Earthy Neutrals | K45: Cotton, Rayon | L45: Mixed | M45: Solid | N45: Casual Basic | O45: 4.8 | P45: 53 | Q45: Limited Availability | R45: 5 | S45: 60% Cotton, 40% Rayon; Limited sizes: Size XL unavailable
A46: Lotty Jacquard Band Jacket | B46: 101828606 | C46: Jackets | D46: Jacquard Jacket | E46: 198 | F46: 198 | G46: Full Price | H46: 0 | I46: Rose Smoke | J46: Earthy Neutrals | K46: Cotton, Polyester | L46: Mixed | M46: Jacquard pattern | N46: Boho | O46: 4.5 | P46: 56 | Q46: Limited Availability | R46: 6 | S46: 60% Cotton 40% Polyester; Limited sizes: Sizes L and XL Unavailable
A47: Salomon XT-6 | B47: 98917701 | C47: Shoes | D47: Sneakers | E47: 180 | F47: 180 | G47: Full Price | H47: 0 | I47: Rainy Day / Paloma / Ftw Silver | J47: Neutrals | K47: Mesh, Textile, Rubber | L47: Mixed | M47: Lace up design | N47: Casual Basic | O47: 3.3 | P47: 35 | Q47: Available | R47: 7 | S47: Reviews mentioned long shipping times and wrong size or color delivered
A48: Rhodes Stud Belt | B48: 93473114 | C48: Accessories | D48: Belts | E48: 48 | F48: 48 | G48: Full Price | H48: 0 | I48: Midnight | J48: Darks | K48: Leather | L48: Natural | M48: Solid/Studded | N48: Everyday Classic | O48: 4.2 | P48: 38 | Q48: Limited Availability | R48: 11 | S48: 100% Leather; Limited sizes: Only size L/XL available
A49: We The Free Ashton Crop Pull-On Cargo Pants | B49: 97310320 | C49: Pants | D49: Cargos | E49: 128 | F49: 128 | G49: Full Price | H49: 0 | I49: Azure | J49: Blues | K49: Cotton | L49: Natural | M49: Solid | N49: Casual Basic | O49: 4.6 | P49: 54 | Q49: Limited Availability | R49: 4 | S49: 100% Cotton; Limited sizes: Size XL unavailable
A50: We The Free Perfect Oversized Tee | B50: 96633029 | C50: Tops | D50: Tees | E50: 38 | F50: 38 | G50: Full Price | H50: 0 | I50: White | J50: White | K50: Cotton | L50: Natural | M50: Solid | N50: Casual Basic | O50: 4.4 | P50: 193 | Q50: Available | R50: 13 | S50: 100% Cotton
... A77: We The Free Scorpio Shirred Mid-Rise Cargo Pants | B77: 102191582 | C77: Pants | D77: Cargos | E77: 168 | F77: 168 | G77: Full Price | H77: 0 | I77: Paprika | J77: Reds | K77: Rayon, Nylon | L77: Synthetic | M77: Solid | N77: Casual Basic | O77: 4.3 | P77: 47 | Q77: Limited Availability | R77: 5 | S77: 82% Rayon, 18% Nylon; Limited sizes: XL unavailable

Sheet Cleaned Data
A1: Free People Bestsellers Analysis
A2: Product Name | B2: Style No. | C2: Product Category | D2: Category Group | E2: Subcategory | F2: Price | G2: Original Price | H2: Sale Status | I2: Discount % | J2: Primary Color | K2: Color Family | L2: Fabric/Material | M2: Material Type | N2: Pattern/Print | O2: Style/aesthetic | P2: Rating (Stars) | Q2: Number of Reviews | R2: Availability | S2: Color Options Count | T2: Notes
A3: Opal Rollneck Knit Sweater | B3: 100632421 | C3: Sweaters | D3: =_xlfn.XLOOKUP(C3,'Lookup Table'!A:A,'Lookup Table'!B:B,"Not Found") -> Apparel | E3: Pullovers | F3: 98 | G3: 98 | H3: Full Price | I3: 0 | J3: Tea | K3: Earthy Neutral | L3: BCI Cotton, Acrylic | M3: Blend | N3: Textured Knit | O3: Casual Basic | P3: 4.2 | Q3: 240 | R3: Limited Availability | S3: 15 | T3: 57% BCI Cotton, 43% Acrylic; Oversized textured knit; Sizes: S and M unavailable
A4: Spotlight Washed Barrel Chino Trousers | B4: 103179669 | C4: Pants | D4: =_xlfn.XLOOKUP(C4,'Lookup Table'!A:A,'Lookup Table'!B:B,"Not Found") -> Apparel | E4: Chino Trousers | F4: 128 | G4: 128 | H4: Full Price | I4: 0 | J4: Tofu | K4: Neutral | L4: Cotton, Rayon, Linen | M4: Blend | N4: Solid | O4: Casual Basic | P4: 4.3 | Q4: 160 | R4: Available | S4: 9 | T4: 56% Cotton, 32% Rayon, 12% Linen; Sizes run small
A5: Spotlight Washed Barrel Chino Trousers | B5: 103179669 | C5: Pants | D5: =_xlfn.XLOOKUP(C5,'Lookup Table'!A:A,'Lookup Table'!B:B,"Not Found") -> Apparel | E5: Chino Trousers | F5: 128 | G5: 128 | H5: Full Price | I5: 0 | J5: Dusty Olive | K5: Earthy Neutral | L5: Cotton, Rayon, Linen | M5: Blend | N5: Solid | O5: Casual Basic | P5: 4.3 | Q5: 160 | R5: Limited Availability | S5: 9 | T5: 56% Cotton, 32% Rayon, 12% Linen; Sizes run small; Long fit size unavailable
A6: Better On Sweatshirt | B6: 100458652 | C6: Tops | D6: =_xlfn.XLOOKUP(C6,'Lookup Table'!A:A,'Lookup Table'!B:B,"Not Found") -> Apparel | E6: Hoodies + Sweatshirts | F6: 78 | G6: 78 | H6: Full Price | I6: 0 | J6: Coconut Milk | K6: White | L6: Cotton | M6: Natural | N6: Solid | O6: Basic Casual | P6: 4.4 | Q6: 31 | R6: Available | S6: 8 | T6: 100% Cotton; Oversized
A7: Chelsea Funnel-Neck Jacket | B7: 107456675 | C7: Jackets | D7: =_xlfn.XLOOKUP(C7,'Lookup Table'!A:A,'Lookup Table'!B:B,"Not Found") -> Apparel | E7: Funnel-Neck Jackets | F7: 168 | G7: 168 | H7: Full Price | I7: 0 | J7: Flint Stone | K7: Grey | L7: Polyester, Cotton, Polyamide | M7: Blend | N7: Solid | O7: Casual Basic | P7: 4.3 | Q7: 11 | R7: Available | S7: 4 | T7: 49% Polyester, 41% Cotton, 10% Polyamide ; Low review count
A8: Margaux Tank | B8: 107496283 | C8: Tops | D8: =_xlfn.XLOOKUP(C8,'Lookup Table'!A:A,'Lookup Table'!B:B,"Not Found") -> Apparel | E8: Tanks | F8: 78 | G8: 78 | H8: Full Price | I8: 0 | J8: White Swan | K8: White | L8: Polyester | M8: Synthetic | N8: Solid | O8: Casual Basic | P8: 4.3 | Q8: 8 | R8: Available | S8: 5 | T8: 100% Polyester; Sizes run small; Low review count
A9: Ventura Oversized Aviator Sunglasses | B9: 60094133 | C9: Accessories | D9: =_xlfn.XLOOKUP(C9,'Lookup Table'!A:A,'Lookup Table'!B:B,"Not Found") -> Accessories | E9: Sunglasses + Eyewear | F9: 25 | G9: 25 | H9: Full Price | I9: 0 | J9: Black/Berry | K9: Dark Neutral | L9: Base Metal, Plastic | M9: Blend | N9: Solid | O9: Retro Aviator | P9: 3.4 | Q9: 139 | R9: Available | S9: 6 | T9: Size inconsistency; Low rating
A10: We The Free Good Luck Barrel Overalls | B10: 86798519 | C10: Jeans | D10: =_xlfn.XLOOKUP(C10,'Lookup Table'!A:A,'Lookup Table'!B:B,"Not Found") -> Apparel | E10: Overalls + Jumpsuits | F10: 148 | G10: 148 | H10: Full Price | I10: 0 | J10: Ultra Light Beam | K10: Blue Denim | M10: Blend | N10: Solid | O10: Casual Basic | P10: 4.3 | Q10: 451 | R10: Limited Availability | S10: 9 | T10: Limited sizes: only L and XL available; Long fit unavailable
A11: We The Free Baby Emerson Tote Bag | B11: 97540942 | C11: Accessories | D11: =_xlfn.XLOOKUP(C11,'Lookup Table'!A:A,'Lookup Table'!B:B,"Not Found") -> Accessories | E11: Bags | F11: 178 | G11: 178 | H11: Full Price | I11: 0 | J11: Salt | K11: White | L11: Leather | M11: Natural | N11: Solid | O11: Everyday Classic | P11: 4.3 | Q11: 415 | R11: Available | S11: 9 | T11: 100% Leather
A12: Margot SoftSpun Sweater Tee | B12: 101764561 | C12: Tops | D12: =_xlfn.XLOOKUP(C12,'Lookup Table'!A:A,'Lookup Table'!B:B,"Not Found") -> Apparel | E12: Tees | F12: 98 | G12: 98 | H12: Full Price | I12: 0 | J12: Marigold Melange | K12: Yellow | L12: Polyester, Acrylic, Polyamide, Elastane | M12: Synthetic | N12: Solid | O12: Casual Basic | P12: 4 | Q12: 43 | R12: Available | S12: 13 | T12: 54% Polyester, 36% Acrylic, 7% Polyamide, 3% Elastane; Oversized; XL unavailable
A13: So Soft Seamless Modal Long Sleeve | B13: 101347284 | C13: Tops | D13: =_xlfn.XLOOKUP(C13,'Lookup Table'!A:A,'Lookup Table'!B:B,"Not Found") -> Apparel | E13: Intimates | F13: 40 | G13: 40 | H13: Full Price | I13: 0 | J13: Whispering Willow | K13: Earthy Neutral | L13: Polyamide, Elastane, Modal | M13: Blend | N13: Solid | O13: Intimates | P13: 4.2 | Q13: 81 | R13: Limited Availability | S13: 12 | T13: 15% Polyamide, 5% Elastane, 80% Modal; Runs small; Sizes: M and L unavailable
A14: Sailor Straw Hat | B14: 107645277 | C14: Accessories | D14: =_xlfn.XLOOKUP(C14,'Lookup Table'!A:A,'Lookup Table'!B:B,"Not Found") -> Accessories | E14: Hats | F14: 38 | G14: 38 | H14: Full Price | I14: 0 | J14: Neutral | K14: Neutral | L14: Paper | M14: Natural | N14: Woven/Open Weave | O14: Everyday Classic | P14: 4.6 | Q14: 7 | R14: Available | S14: 5 | T14: 100% Paper; Low review count
A15: So Silk Badana | B15: 96577754 | C15: Accessories | D15: =_xlfn.XLOOKUP(C15,'Lookup Table'!A:A,'Lookup Table'!B:B,"Not Found") -> Accessories | E15: Scarves + Bandanas | F15: 48 | G15: 48 | H15: Full Price | I15: 0 | J15: Springtime Print Chocolate | K15: Earthy Neutral | L15: Silk | M15: Natural | N15: Paisley Print | O15: Everyday Classic | P15: 4 | Q15: 42 | R15: Available | S15: 13 | T15: 100% Silk
A16: See You Soon Studded Tote | B16: 100468586 | C16: Accessories | D16: =_xlfn.XLOOKUP(C16,'Lookup Table'!A:A,'Lookup Table'!B:B,"Not Found") -> Accessories | E16: Bags | F16: 198 | G16: 198 | H16: Full Price | I16: 0 | J16: Bitter Bark | K16: Dark Neutral | L16: Leather | M16: Natural | N16: Solid/Studded | O16: Everyday Classic | P16: 4.1 | Q16: 7 | R16: Available | S16: 2 | T16: 100% Leather; Studded; Low review count
A17: We The Free Peggy Tee | B17: 107581175 | C17: Tops | D17: =_xlfn.XLOOKUP(C17,'Lookup Table'!A:A,'Lookup Table'!B:B,"Not Found") -> Apparel | E17: Tees | F17: 48 | G17: 48 | H17: Full Price | I17: 0 | J17: Clean Ivory | K17: Off-White | L17: Cotton | M17: Natural | N17: Solid | O17: Casual Basic | P17: 4.3 | Q17: 22 | R17: Limited Availability | S17: 7 | T17: 100% Cotton; Limited sizes: only sizes: L and XL available
A18: Opal Knit Cardi | B18: 105616825 | C18: Sweaters | D18: =_xlfn.XLOOKUP(C18,'Lookup Table'!A:A,'Lookup Table'!B:B,"Not Found") -> Apparel | E18: Cardigans | F18: 168 | G18: 168 | H18: Full Price | I18: 0 | J18: Black | K18: Dark Neutral | L18: Cotton, Acrylic | M18: Blend | N18: Textured Knit | O18: Cozy | P18: 4 | Q18: 33 | R18: Available | S18: 3 | T18: 57% Cotton, 43% Acrylic
A19: Mismatch Magnolia Sandals | B19: 99005373 | C19: Shoes | D19: =_xlfn.XLOOKUP(C19,'Lookup Table'!A:A,'Lookup Table'!B:B,"Not Found") -> Footwear | E19: Sandals | F19: 128 | G19: 128 | H19: Full Price | I19: 0 | J19: Tan Suede | K19: Earthy Neutral | L19: Leather, Rubber | M19: Blend | N19: Solid/Floral Detail | O19: Everyday Classic | P19: 4.1 | Q19: 21 | R19: Limited Availability | S19: 5 | T19: Limited sizes: only size US 6 available
A20: We The Free Opal Swing Denim Jacket | B20: 68349745 | C20: Jackets | D20: =_xlfn.XLOOKUP(C20,'Lookup Table'!A:A,'Lookup Table'!B:B,"Not Found") -> Apparel | E20: Denim Jackets | F20: 128 | G20: 128 | H20: Full Price | I20: 0 | J20: Dusted Cocoa | K20: Earthy Neutral | L20: Cotton | M20: Natural | N20: Solid | O20: Casual Basic | P20: 4.6 | Q20: 340 | R20: Available | S20: 4 | T20: 100% Cotton; Oversized
A21: Jojo Washed Oversized Funnel-Neck Jacket | B21: 104773247 | C21: Jackets | D21: =_xlfn.XLOOKUP(C21,'Lookup Table'!A:A,'Lookup Table'!B:B,"Not Found") -> Apparel | E21: Barns + Utility | F21: 198 | G21: 198 | H21: Full Price | I21: 0 | J21: Brown Bear | K21: Earthy Neutral | L21: Cotton | M21: Natural | N21: Solid | O21: Basic Casual | P21: 3.7 | Q21: 7 | R21: Available | S21: 3 | T21: 100% Cotton; Oversized
A22: Dolman Quilted Knit Jacket | B22: 63857528 | C22: Jackets | D22: =_xlfn.XLOOKUP(C22,'Lookup Table'!A:A,'Lookup Table'!B:B,"Not Found") -> Apparel | E22: Quilted Knitted Jackets | F22: 198 | G22: 198 | H22: Full Price | I22: 0 | J22: Champagne Diamonds | K22: Earthy Neutral | L22: Cotton, Polyester | M22: Blend | N22: Quilted Knit | O22: Basic Casual | P22: 4.5 | Q22: 897 | R22: Limited Availability | S22: 5 | T22: 100% Cotton, Filling: 100% Polyester; Oversized; Limited sizes: Size S unavailable
... A35: We The Free Palm Springs Pullover | B35: 96774302 | C35: Sweaters | D35: =_xlfn.XLOOKUP(C35,'Lookup Table'!A:A,'Lookup Table'!B:B,"Not Found") -> Apparel | E35: Pullovers | F35: 78 | G35: 78 | H35: Full Price | I35: 0 | J35: Clean Ivory | K35: Off-White | L35: Cotton | M35: Natural | N35: Solid | O35: Casual Basic | P35: 4.4 | Q35: 142 | R35: Available | S35: 12 | T35: 100% Cotton; Oversized
A36: Lady Lux Layering Top | B36: 58381005 | C36: Tops | D36: =_xlfn.XLOOKUP(C36,'Lookup Table'!A:A,'Lookup Table'!B:B,"Not Found") -> Apparel | E36: Intimates | F36: 40 | G36: 40 | H36: Full Price | I36: 0 | J36: Black | K36: Dark Neutral | L36: Elastane, Nylon | M36: Synthetic | N36: Floral | O36: Intimates | P36: 4.4 | Q36: 727 | R36: Limited Availability | S36: 13 | T36: 15% Elastane, 85% Nylon; Limited sizes: M, L, and XL unavailable
A37: Sabo East West Bag | B37: 100073840 | C37: Accessories | D37: =_xlfn.XLOOKUP(C37,'Lookup Table'!A:A,'Lookup Table'!B:B,"Not Found") -> Accessories | E37: Bags | F37: 148 | G37: 148 | H37: Full Price | I37: 0 | J37: Saddle | K37: Earthy Neutral | L37: Leather | M37: Natural | N37: Solid | O37: Casual Basic | P37: 3.5 | Q37: 8 | R37: Available | S37: 1 | T37: Low review count
A38: Tilly Skinny Silk Convertible Scarf | B38: 101374734 | C38: Accessories | D38: =_xlfn.XLOOKUP(C38,'Lookup Table'!A:A,'Lookup Table'!B:B,"Not Found") -> Accessories | E38: Scarves + Bandanas | F38: 28 | G38: 28 | H38: Full Price | I38: 0 | J38: Ditsy Dots Pink | K38: Pink | L38: Silk | M38: Natural | N38: Floral | O38: Boho | P38: 4 | Q38: 49 | R38: Available | S38: 11 | T38: 100% Silk
A39: We The Free Montana Shorts | B39: 94588803 | C39: Pants | D39: =_xlfn.XLOOKUP(C39,'Lookup Table'!A:A,'Lookup Table'!B:B,"Not Found") -> Apparel | E39: Shorts | F39: 78 | G39: 78 | H39: Full Price | I39: 0 | J39: Haven | K39: Blue Denim | L39: Cotton | M39: Natural | N39: Solid | O39: Casual Basic | P39: 4.1 | Q39: 85 | R39: Limited Availability | S39: 6 | T39: 100% Cotton
A40: VIBAe Roma Mules | B40: 98060296 | C40: Shoes | D40: =_xlfn.XLOOKUP(C40,'Lookup Table'!A:A,'Lookup Table'!B:B,"Not Found") -> Footwear | E40: Mules | F40: 200 | G40: 200 | H40: Full Price | I40: 0 | J40: Cognac Brown | K40: Earthy Neutral | L40: Leather, Rubber | M40: Blend | N40: Solid | O40: Casual Basic | P40: 4.9 | Q40: 19 | R40: Available | S40: 5 | T40: Limited sizes: Sizes 26 and 27 unavailable
A41: We The Free Baby Asher Tote | B41: 106790777 | C41: Accessories | D41: =_xlfn.XLOOKUP(C41,'Lookup Table'!A:A,'Lookup Table'!B:B,"Not Found") -> Accessories | E41: Bags | F41: 198 | G41: 198 | H41: Full Price | I41: 0 | J41: Espresso | K41: Earthy Neutral | L41: Leather | M41: Natural | N41: Solid | O41: Everyday Classic | P41: 4 | Q41: 7 | R41: Available | S41: 3 | T41: Limited review count
A42: We The Free Fringe Out Vegan Suede Jacket | B42: 87495743 | C42: Jackets | D42: =_xlfn.XLOOKUP(C42,'Lookup Table'!A:A,'Lookup Table'!B:B,"Not Found") -> Apparel | E42: Fringe Jackets | F42: 168 | G42: 168 | H42: Full Price | I42: 0 | J42: Toasted Coconut | K42: Earthy Neutral | L42: Polyester, Elastane | M42: Synthetic | N42: Fringe | O42: Vintage | P42: 4.4 | Q42: 78 | R42: Available | S42: 3 | T42: 87% Polyester; 13% Elastane; Oversized
A43: Belle Rosette Claw Clip | B43: 106139603 | C43: Accessories | D43: =_xlfn.XLOOKUP(C43,'Lookup Table'!A:A,'Lookup Table'!B:B,"Not Found") -> Accessories | E43: Hair Clips | F43: 18 | G43: 18 | H43: Full Price | I43: 0 | J43: Sage | K43: Earthy Neutral | L43: Polyester, Plastic | M43: Synthetic | N43: Solid | O43: Romantic | P43: 4.4 | Q43: 7 | R43: Available | S43: 5 | T43: 60% Polyester, 40% Plastic; Low review count
A44: Understated Leather Wide Eyes Suede Fringe Collar | B44: 100212216 | C44: Accessories | D44: =_xlfn.XLOOKUP(C44,'Lookup Table'!A:A,'Lookup Table'!B:B,"Not Found") -> Accessories | E44: Scarves + Bandanas | F44: 98 | G44: 98 | H44: Full Price | I44: 0 | J44: Moss | K44: Earthy Neutral | L44: Leather | M44: Natural | N44: Fringe | O44: Vintage | P44: 4.6 | Q44: 29 | R44: Available | S44: 5 | T44: 100% Leather
A45: Moonflower Pull-On Balloon Pants | B45: 104179064 | C45: Pants | D45: =_xlfn.XLOOKUP(C45,'Lookup Table'!A:A,'Lookup Table'!B:B,"Not Found") -> Apparel | E45: Balloon Pants | F45: 98 | G45: 98 | H45: Full Price | I45: 0 | J45: Sage | K45: Earthy Neutral | L45: Cotton, Rayon | M45: Blend | N45: Solid | O45: Casual Basic | P45: 4.8 | Q45: 53 | R45: Limited Availability | S45: 5 | T45: 60% Cotton, 40% Rayon; Limited sizes: Size XL unavailable
A46: Lotty Jacquard Band Jacket | B46: 101828606 | C46: Jackets | D46: =_xlfn.XLOOKUP(C46,'Lookup Table'!A:A,'Lookup Table'!B:B,"Not Found") -> Apparel | E46: Jacquard Jackets | F46: 198 | G46: 198 | H46: Full Price | I46: 0 | J46: Rose Smoke | K46: Pink | L46: Cotton, Polyester | M46: Blend | N46: Jacquard pattern | O46: Boho | P46: 4.5 | Q46: 56 | R46: Limited Availability | S46: 6 | T46: 60% Cotton 40% Polyester; Limited sizes: Sizes L and XL unavailable
A47: Salomon XT-6 | B47: 98917701 | C47: Shoes | D47: =_xlfn.XLOOKUP(C47,'Lookup Table'!A:A,'Lookup Table'!B:B,"Not Found") -> Footwear | E47: Sneakers | F47: 180 | G47: 180 | H47: Full Price | I47: 0 | J47: Rainy Day / Paloma / Ftw Silver | K47: Neutral | L47: Mesh, Textile, Rubber | M47: Blend | N47: Lace up design | O47: Casual Basic | P47: 3.3 | Q47: 35 | R47: Available | S47: 7 | T47: Reviews mentioned long shipping times and wrong size or color delivered
A48: Rhodes Stud Belt | B48: 93473114 | C48: Accessories | D48: =_xlfn.XLOOKUP(C48,'Lookup Table'!A:A,'Lookup Table'!B:B,"Not Found") -> Accessories | E48: Belts | F48: 48 | G48: 48 | H48: Full Price | I48: 0 | J48: Midnight | K48: Dark Neutral | L48: Leather | M48: Natural | N48: Solid/Studded | O48: Everyday Classic | P48: 4.2 | Q48: 38 | R48: Limited Availability | S48: 11 | T48: 100% Leather; Limited sizes: only size L/XL available
A49: We The Free Ashton Crop Pull-On Cargo Pants | B49: 97310320 | C49: Pants | D49: =_xlfn.XLOOKUP(C49,'Lookup Table'!A:A,'Lookup Table'!B:B,"Not Found") -> Apparel | E49: Cargos | F49: 128 | G49: 128 | H49: Full Price | I49: 0 | J49: Azure | K49: Blue | L49: Cotton | M49: Natural | N49: Solid | O49: Casual Basic | P49: 4.6 | Q49: 54 | R49: Limited Availability | S49: 4 | T49: 100% Cotton; Limited sizes: Size XL unavailable
A50: We The Free Perfect Oversized Tee | B50: 96633029 | C50: Tops | D50: =_xlfn.XLOOKUP(C50,'Lookup Table'!A:A,'Lookup Table'!B:B,"Not Found") -> Apparel | E50: Tees | F50: 38 | G50: 38 | H50: Full Price | I50: 0 | J50: White | K50: White | L50: Cotton | M50: Natural | N50: Solid | O50: Casual Basic | P50: 4.4 | Q50: 193 | R50: Available | S50: 13 | T50: 100% Cotton
... A77: We The Free Scorpio Shirred Mid-Rise Cargo Pants | B77: 102191582 | C77: Pants | D77: =_xlfn.XLOOKUP(C77,'Lookup Table'!A:A,'Lookup Table'!B:B,"Not Found") -> Apparel | E77: Cargos | F77: 168 | G77: 168 | H77: Full Price | I77: 0 | J77: Paprika | K77: Red | L77: Rayon, Nylon | M77: Synthetic | N77: Solid | O77: Casual Basic | P77: 4.3 | Q77: 47 | R77: Limited Availability | S77: 5 | T77: 82% Rayon, 18% Nylon; Limited sizes: XL unavailable

Sheet Pivot Tables
A1: Product Category Count
A3: Product Category | B3: Product Count
A4: Pants | B4: 24
A5: Accessories | B5: 15
A6: Tops | B6: 11
A7: Jackets | B7: 7
A8: Shoes | B8: 6
A9: Sweaters | B9: 6
A10: Jeans | B10: 2
A11: Sets | B11: 1
A12: Intimates | B12: 1
A13: Dresses | B13: 1
A14: Jumpsuits | B14: 1
A15: Grand Total | B15: 75
A20: Color Family Count
A22: Color Family | B22: Product Count
A23: Earthy Neutral | B23: 18
A24: Blue Denim | B24: 12
A25: Dark Neutral | B25: 8
A26: Pink | B26: 8
A27: Off-White | B27: 5
A28: White | B28: 5
A29: Neutral | B29: 4
A30: Green | B30: 4
A31: Yellow | B31: 3
A32: Red | B32: 2
A33: Blue | B33: 2
A34: Grey | B34: 2
... A36: Grand Total | B36: 75
A42: Material Type Count
A44: Material Type | B44: Product Count
A45: Natural | B45: 41
A46: Blend | B46: 27
A47: Synthetic | B47: 7
A48: Grand Total | B48: 75
A55: Average Price by Product Category
A57: Product Category | B57: Average Price
A58: Shoes | B58: 214.33333
A59: Jackets | B59: 169.42857
A60: Sets | B60: 128
...

Sheet Charts
A1: Free People Bestsellers Analysis: Charts

Sheet Lookup Table
A1: Product Category | B1: Category Group
A2: Accessories | B2: Accessories
A3: Dresses | B3: Apparel
A4: Intimates | B4: Apparel
A5: Jackets | B5: Apparel
A6: Jeans | B6: Apparel
A7: Jumpsuits | B7: Apparel
A8: Pants | B8: Apparel
A9: Sets | B9: Apparel
A10: Shoes | B10: Footwear
A11: Sweaters | B11: Apparel
A12: Tops | B12: Apparel
